<?xml version="1.0" ?>
<!--
  Try sending commands:
    gz topic -t "/model/diff_drive/cmd_vel" -m gz.msgs.Twist -p "linear: {x: 1.0}, angular: {z: -0.1}"
    ros2 topic pub /diff_drive/cmd_vel geometry_msgs/msg/Twist "{linear: {x: 5.0, y: 0.0, z: 0.0}, angular: {x: 0.0, y: 0.0, z: -0.1}}"
  Listen to odometry:
    gz topic -e -t /model/diff_drive/odometry
    ros2 topic echo /model/diff_drive/odometry
-->
<sdf version="1.8">
  <world name="demo">
    <plugin
      filename="gz-sim-physics-system"
      name="gz::sim::systems::Physics">
    </plugin>
    <plugin
      filename="gz-sim-sensors-system"
      name="gz::sim::systems::Sensors">
      <render_engine>ogre2</render_engine>
    </plugin>
    <plugin
      filename="gz-sim-scene-broadcaster-system"
      name="gz::sim::systems::SceneBroadcaster">
    </plugin>
    <plugin
      filename="gz-sim-user-commands-system"
      name="gz::sim::systems::UserCommands">
    </plugin>
    <plugin
      filename="BasicSystem"
      name="ros_gz_example_gazebo::BasicSystem">
    </plugin>
    <plugin
      filename="FullSystem"
      name="ros_gz_example_gazebo::FullSystem">
    </plugin>

    <light name="sun" type="directional">
      <cast_shadows>true</cast_shadows>
      <pose>0 0 10 0 0 0</pose>
      <diffuse>0.8 0.8 0.8 1</diffuse>
      <specular>0.2 0.2 0.2 1</specular>
      <attenuation>
        <range>1000</range>
        <constant>0.9</constant>
        <linear>0.01</linear>
        <quadratic>0.001</quadratic>
      </attenuation>
      <direction>-0.5 0.1 -0.9</direction>
    </light>

    <model name="ground_plane">
      <static>true</static>
      <link name="link">
        <collision name="collision">
          <geometry>
            <plane>
              <normal>0 0 1</normal>
              <size>100 100</size>
            </plane>
          </geometry>
        </collision>
        <visual name="visual">
          <geometry>
            <plane>
              <normal>0 0 1</normal>
              <size>100 100</size>
            </plane>
          </geometry>
          <material>
            <ambient>0.8 0.8 0.8 1</ambient>
            <diffuse>0.8 0.8 0.8 1</diffuse>
            <specular>0.8 0.8 0.8 1</specular>
          </material>
        </visual>
      </link>
    </model>

    <model name="diff_drive">
      <self_collide>true</self_collide>
      <pose>0 0 0.35 0 0 0</pose>

        <link name='chassis'>
          <pose>-0.151427 -0 0.175 0 -0 0</pose>
          <inertial>
            <mass>1.14395</mass>
            <inertia>
              <ixx>0.126164</ixx>
              <ixy>0</ixy>
              <ixz>0</ixz>
              <iyy>0.416519</iyy>
              <iyz>0</iyz>
              <izz>0.481014</izz>
            </inertia>
          </inertial>
          <visual name='visual_chassis'>
            <geometry>
              <box>
                <size>2.01142 1 0.568726</size>
              </box>
            </geometry>
            <material>
              <ambient>0.5 0.5 1.0 1</ambient>
              <diffuse>0.5 0.5 1.0 1</diffuse>
              <specular>0.0 0.0 1.0 1</specular>
            </material>
          </visual>
          <collision name='collision_chassis'>
            <geometry>
              <box>
                <size>2.01142 1 0.568726</size>
              </box>
            </geometry>
          </collision>
        </link>

        <link name='left_wheel'>
          <pose>0.554283 0.625029 -0.025 -1.5707 0 0</pose>
          <inertial>
            <mass>2</mass>
            <inertia>
              <ixx>0.145833</ixx>
              <ixy>0</ixy>
              <ixz>0</ixz>
              <iyy>0.145833</iyy>
              <iyz>0</iyz>
              <izz>0.125</izz>
            </inertia>
          </inertial>
          <visual name='visual_left_wheel'>
            <geometry>
              <sphere>
                <radius>0.3</radius>
              </sphere>
            </geometry>
            <material>
              <ambient>0.2 0.2 0.2 1</ambient>
              <diffuse>0.2 0.2 0.2 1</diffuse>
              <specular>0.2 0.2 0.2 1</specular>
            </material>
          </visual>
          <collision name='collision_left_wheel'>
            <geometry>
              <sphere>
                <radius>0.3</radius>
              </sphere>
            </geometry>
          </collision>
        </link>

        <link name='right_wheel'>
          <pose>0.554282 -0.625029 -0.025 -1.5707 0 0</pose>
          <inertial>
            <mass>2</mass>
            <inertia>
              <ixx>0.145833</ixx>
              <ixy>0</ixy>
              <ixz>0</ixz>
              <iyy>0.145833</iyy>
              <iyz>0</iyz>
              <izz>0.125</izz>
            </inertia>
          </inertial>
          <visual name='visual_right_wheel'>
            <geometry>
              <sphere>
                <radius>0.3</radius>
              </sphere>
            </geometry>
            <material>
              <ambient>0.2 0.2 0.2 1</ambient>
              <diffuse>0.2 0.2 0.2 1</diffuse>
              <specular>0.2 0.2 0.2 1</specular>
            </material>
          </visual>
          <collision name='collision_right_wheel'>
            <geometry>
              <sphere>
                <radius>0.3</radius>
              </sphere>
            </geometry>
          </collision>
        </link>

        <link name='caster'>
          <pose>-0.957138 -0 -0.125 0 -0 0</pose>
          <inertial>
            <mass>1</mass>
            <inertia>
              <ixx>0.1</ixx>
              <ixy>0</ixy>
              <ixz>0</ixz>
              <iyy>0.1</iyy>
              <iyz>0</iyz>
              <izz>0.1</izz>
            </inertia>
          </inertial>
          <visual name='visual_caster'>
            <geometry>
              <sphere>
                <radius>0.2</radius>
              </sphere>
            </geometry>
            <material>
              <ambient>0.2 0.2 0.2 1</ambient>
              <diffuse>0.2 0.2 0.2 1</diffuse>
              <specular>0.2 0.2 0.2 1</specular>
            </material>
          </visual>
          <collision name='collision_caster'>
            <geometry>
              <sphere>
                <radius>0.2</radius>
              </sphere>
            </geometry>
          </collision>
        </link>

        <link name="lidar_link">
          <pose>0 0 0.5 0 0 0</pose>
          <inertial>
            <mass>0.1</mass>
            <inertia>
              <ixx>0.000166667</ixx>
              <iyy>0.000166667</iyy>
              <izz>0.000166667</izz>
            </inertia>
          </inertial>
          <collision name="collision">
            <geometry>
              <box>
                <size>0.1 0.1 0.1</size>
              </box>
            </geometry>
          </collision>
          <visual name="visual">
            <geometry>
              <box>
                <size>0.1 0.1 0.1</size>
              </box>
            </geometry>
          </visual>

        </link>

        <joint name='lidar_joint' type='fixed'>
          <parent>chassis</parent>
          <child>lidar_link</child>
        </joint>

        <joint name='left_wheel_joint' type='revolute'>
          <parent>chassis</parent>
          <child>left_wheel</child>
          <axis>
            <xyz>0 0 1</xyz>
            <limit>
              <lower>-1.79769e+308</lower>
              <upper>1.79769e+308</upper>
            </limit>
          </axis>
        </joint>

        <joint name='right_wheel_joint' type='revolute'>
          <parent>chassis</parent>
          <child>right_wheel</child>
          <axis>
            <xyz>0 0 1</xyz>
            <limit>
              <lower>-1.79769e+308</lower>
              <upper>1.79769e+308</upper>
            </limit>
          </axis>
        </joint>

        <joint name='caster_wheel' type='ball'>
          <parent>chassis</parent>
          <child>caster</child>
        </joint>

        <plugin
          filename="ignition-gazebo-diff-drive-system"
          name="ignition::gazebo::systems::DiffDrive">
          <left_joint>left_wheel_joint</left_joint>
          <right_joint>right_wheel_joint</right_joint>
          <wheel_separation>1.25</wheel_separation>
          <wheel_radius>0.3</wheel_radius>
          <odom_publish_frequency>1</odom_publish_frequency>
          <max_linear_acceleration>1</max_linear_acceleration>
          <min_linear_acceleration>-1</min_linear_acceleration>
          <max_angular_acceleration>2</max_angular_acceleration>
          <min_angular_acceleration>-2</min_angular_acceleration>
          <max_linear_velocity>0.5</max_linear_velocity>
          <min_linear_velocity>-0.5</min_linear_velocity>
          <max_angular_velocity>1</max_angular_velocity>
          <min_angular_velocity>-1</min_angular_velocity>
        </plugin>

      <plugin
        filename="gz-sim-joint-state-publisher-system"
        name="gz::sim::systems::JointStatePublisher">
      </plugin>

      <plugin
        filename="gz-sim-pose-publisher-system"
        name="gz::sim::systems::PosePublisher">
        <publish_link_pose>true</publish_link_pose>
        <use_pose_vector_msg>true</use_pose_vector_msg>
        <static_publisher>true</static_publisher>
        <static_update_frequency>1</static_update_frequency>
      </plugin>

      <plugin
        filename="gz-sim-odometry-publisher-system"
        name="gz::sim::systems::OdometryPublisher">
        <odom_frame>diff_drive/odom</odom_frame>
        <robot_base_frame>diff_drive</robot_base_frame>
      </plugin>
    </model>

  </world>
</sdf>
